"""
Error Handling Tests
===================

Tests for comprehensive error handling, exception management,
and system resilience across V2_SWARM components.

Author: Agent-8 (Operations & Support Specialist)
"""

import sys
import time
from unittest.mock import Mock, patch

import pytest

# Import error handling components
try:
    from src.core.error_handling_unified import UnifiedErrorHandler
    from src.core.unified_logging_system import UnifiedLoggingSystem

    ERROR_HANDLING_AVAILABLE = True
except ImportError:
    ERROR_HANDLING_AVAILABLE = False

    # Create mock classes
    class UnifiedErrorHandler:
        def handle_error(self, *args, **kwargs):
            return None

        def log_error(self, *args, **kwargs):
            return None

    class UnifiedLoggingSystem:
        def log_error(self, *args, **kwargs):
            pass


@pytest.mark.operational
class TestUnifiedErrorHandler:
    """Test unified error handling system."""

    def test_error_classification(self):
        """Test proper classification of different error types."""
        error_handler = UnifiedErrorHandler()

        test_errors = [
            (ValueError("Invalid value"), "ValueError"),
            (KeyError("Missing key"), "KeyError"),
            (FileNotFoundError("File not found"), "FileNotFoundError"),
            (ConnectionError("Connection failed"), "ConnectionError"),
            (TimeoutError("Operation timed out"), "TimeoutError"),
        ]

        for error, expected_type in test_errors:
            try:
                raise error
            except Exception as e:
                # Test error classification
                error_info = error_handler.handle_error(e)
                if error_info:
                    assert "error_type" in error_info
                    assert expected_type in error_info["error_type"]

    def test_error_logging(self):
        """Test error logging functionality."""
        error_handler = UnifiedErrorHandler()

        # Test logging various error types
        test_scenarios = [
            ValueError("Test value error"),
            RuntimeError("Test runtime error"),
            SystemError("Test system error"),
        ]

        for error in test_scenarios:
            # Should handle logging without raising exceptions
            try:
                error_handler.log_error(error, "test_component")
            except Exception as e:
                # Only acceptable if it's a logging-related error
                assert "log" in str(e).lower()

    def test_error_recovery_mechanisms(self):
        """Test error recovery and retry mechanisms."""
        error_handler = UnifiedErrorHandler()

        # Test retry logic
        retry_count = 0
        max_retries = 3

        def failing_operation():
            nonlocal retry_count
            retry_count += 1
            if retry_count < max_retries:
                raise ConnectionError("Temporary connection failure")
            return "success"

        # Test retry wrapper (if available)
        try:
            result = failing_operation()
            if retry_count >= max_retries:
                assert result == "success"
        except Exception:
            # If no retry mechanism, just ensure operation doesn't crash
            pass

    def test_graceful_degradation(self):
        """Test graceful degradation under error conditions."""
        error_handler = UnifiedErrorHandler()

        # Test system behavior when components fail
        with patch(
            "src.core.unified_logging_system.UnifiedLoggingSystem", create=True
        ) as mock_logging_class:
            mock_logger = Mock()
            mock_logger.log_error.side_effect = Exception("Logger failure")
            mock_logging_class.return_value = mock_logger

            # System should continue operating despite logger failure
            try:
                error_handler.log_error(ValueError("Test error"), "test_component")
                # Should not raise unhandled exceptions
            except Exception as e:
                # Only logger-related errors should propagate
                assert "log" in str(e).lower()


@pytest.mark.operational
class TestExceptionManagement:
    """Test comprehensive exception management."""

    def test_exception_chaining(self):
        """Test proper exception chaining and context preservation."""
        try:
            try:
                raise ValueError("Original error")
            except ValueError as original:
                raise RuntimeError("Wrapper error") from original
        except RuntimeError as wrapper:
            # Should preserve original exception
            assert wrapper.__cause__ is not None
            assert isinstance(wrapper.__cause__, ValueError)
            assert str(wrapper.__cause__) == "Original error"

    def test_custom_exception_hierarchy(self):
        """Test custom exception hierarchy for V2_SWARM."""

        # Define custom exception hierarchy
        class SwarmException(Exception):
            """Base exception for V2_SWARM."""

            pass

        class OperationalException(SwarmException):
            """Operational error."""

            pass

        class ConfigurationException(SwarmException):
            """Configuration error."""

            pass

        # Test exception hierarchy
        try:
            raise OperationalException("Test operational error")
        except SwarmException as e:
            assert isinstance(e, OperationalException)
            assert "operational" in str(e).lower()

        try:
            raise ConfigurationException("Test configuration error")
        except SwarmException as e:
            assert isinstance(e, ConfigurationException)
            assert "configuration" in str(e).lower()

    def test_error_context_preservation(self):
        """Test preservation of error context and debugging information."""

        def operation_with_context():
            """Simulate operation that provides context."""
            context = {
                "operation": "test_operation",
                "parameters": {"param1": "value1"},
                "timestamp": time.time(),
                "component": "test_component",
            }
            raise ValueError("Operation failed")

        try:
            operation_with_context()
        except ValueError as e:
            # Error should be catchable and context preservable
            assert "Operation failed" in str(e)

            # In a real system, context would be logged or attached
            # For testing, we verify the error is properly raised and catchable


@pytest.mark.operational
class TestSystemResilience:
    """Test system resilience and fault tolerance."""

    def test_service_degradation_handling(self):
        """Test handling of service degradation scenarios."""
        # Simulate service becoming unavailable
        service_available = True

        def unreliable_service():
            nonlocal service_available
            if not service_available:
                raise ConnectionError("Service temporarily unavailable")
            return "service_response"

        # Test with service available
        result = unreliable_service()
        assert result == "service_response"

        # Test with service unavailable
        service_available = False
        with pytest.raises(ConnectionError):
            unreliable_service()

    def test_circuit_breaker_pattern(self):
        """Test circuit breaker pattern for fault tolerance."""

        class CircuitBreaker:
            def __init__(self, failure_threshold=3):
                self.failure_count = 0
                self.failure_threshold = failure_threshold
                self.state = "closed"  # closed, open, half-open

            def call(self, operation):
                if self.state == "open":
                    raise Exception("Circuit breaker is open")

                try:
                    result = operation()
                    self._on_success()
                    return result
                except Exception as e:
                    self._on_failure()
                    raise e

            def _on_success(self):
                self.failure_count = 0
                self.state = "closed"

            def _on_failure(self):
                self.failure_count += 1
                if self.failure_count >= self.failure_threshold:
                    self.state = "open"

        breaker = CircuitBreaker()

        # Test successful operations
        result = breaker.call(lambda: "success")
        assert result == "success"
        assert breaker.state == "closed"

        # Test failure handling
        failure_count = 0

        def failing_operation():
            nonlocal failure_count
            failure_count += 1
            raise ValueError(f"Failure {failure_count}")

        # Should handle failures up to threshold
        for i in range(2):
            with pytest.raises(ValueError):
                breaker.call(failing_operation)

        # Should still be closed
        assert breaker.state == "closed"

        # Third failure should open circuit
        with pytest.raises(ValueError):
            breaker.call(failing_operation)
        assert breaker.state == "open"

        # Subsequent calls should fail fast
        with pytest.raises(Exception, match="Circuit breaker is open"):
            breaker.call(lambda: "should not execute")

    def test_fallback_mechanisms(self):
        """Test fallback mechanisms for system resilience."""

        def primary_operation():
            raise ConnectionError("Primary service unavailable")

        def fallback_operation():
            return "fallback_response"

        # Test fallback execution
        result = None
        try:
            result = primary_operation()
        except ConnectionError:
            result = fallback_operation()

        assert result == "fallback_response"


@pytest.mark.operational
class TestErrorRecoveryScenarios:
    """Test various error recovery scenarios."""

    def test_network_error_recovery(self):
        """Test recovery from network-related errors."""
        network_errors = [
            ConnectionError("Connection refused"),
            TimeoutError("Operation timed out"),
            OSError("Network unreachable"),
        ]

        for error in network_errors:
            with pytest.raises(type(error)):
                raise error

            # In real system, would test retry logic
            # For now, verify error types are correct

    def test_file_system_error_recovery(self):
        """Test recovery from file system errors."""
        file_errors = [
            FileNotFoundError("File not found"),
            PermissionError("Permission denied"),
            IsADirectoryError("Is a directory"),
            OSError("Disk full"),
        ]

        for error in file_errors:
            with pytest.raises(type(error)):
                raise error

    def test_resource_error_recovery(self):
        """Test recovery from resource exhaustion errors."""
        resource_errors = [
            MemoryError("Memory exhausted"),
            RecursionError("Maximum recursion depth exceeded"),
        ]

        for error in resource_errors:
            with pytest.raises(type(error)):
                raise error


@pytest.mark.operational
class TestErrorReportingAndMonitoring:
    """Test error reporting and monitoring systems."""

    def test_error_aggregation(self):
        """Test aggregation of multiple errors."""
        errors = []

        # Simulate multiple error scenarios
        error_scenarios = [
            (ValueError("Value error"), "input_validation"),
            (KeyError("Key error"), "data_processing"),
            (ConnectionError("Connection error"), "network_communication"),
            (TimeoutError("Timeout error"), "external_service"),
        ]

        for error, component in error_scenarios:
            error_info = {
                "error": str(error),
                "type": type(error).__name__,
                "component": component,
                "timestamp": time.time(),
            }
            errors.append(error_info)

        # Verify error aggregation
        assert len(errors) == len(error_scenarios)

        # Check error categorization
        error_types = [e["type"] for e in errors]
        assert "ValueError" in error_types
        assert "KeyError" in error_types
        assert "ConnectionError" in error_types
        assert "TimeoutError" in error_types

    def test_error_trending_analysis(self):
        """Test analysis of error trends over time."""
        # Simulate error patterns over time
        error_timeline = [
            {"timestamp": time.time(), "error_type": "ConnectionError", "component": "api"},
            {"timestamp": time.time() + 1, "error_type": "TimeoutError", "component": "api"},
            {"timestamp": time.time() + 2, "error_type": "ConnectionError", "component": "api"},
            {"timestamp": time.time() + 3, "error_type": "ValueError", "component": "processing"},
        ]

        # Analyze error patterns
        error_counts = {}
        component_errors = {}

        for error in error_timeline:
            error_type = error["error_type"]
            component = error["component"]

            error_counts[error_type] = error_counts.get(error_type, 0) + 1
            if component not in component_errors:
                component_errors[component] = {}
            component_errors[component][error_type] = (
                component_errors[component].get(error_type, 0) + 1
            )

        # Verify analysis
        assert error_counts["ConnectionError"] == 2
        assert error_counts["TimeoutError"] == 1
        assert error_counts["ValueError"] == 1

        assert "api" in component_errors
        assert "processing" in component_errors


@pytest.mark.operational
class TestBoundaryConditionHandling:
    """Test handling of boundary conditions and edge cases."""

    def test_null_and_empty_value_handling(self):
        """Test handling of null and empty values."""
        test_cases = [
            None,
            "",
            [],
            {},
            0,
            False,
        ]

        for test_value in test_cases:
            # Test that system can handle these values without crashing
            try:
                # Simulate processing of various input types
                if test_value is None:
                    result = "null_handled"
                elif test_value == "":
                    result = "empty_handled"
                elif isinstance(test_value, list) and len(test_value) == 0:
                    result = "empty_list_handled"
                elif isinstance(test_value, dict) and len(test_value) == 0:
                    result = "empty_dict_handled"
                else:
                    result = f"value_{test_value}_handled"

                assert result is not None
                assert "handled" in result

            except Exception as e:
                # Should handle edge cases gracefully
                assert "handled" in str(e).lower() or isinstance(e, (TypeError, ValueError))

    def test_extreme_value_handling(self):
        """Test handling of extreme values."""
        extreme_values = [
            float("inf"),
            float("-inf"),
            float("nan"),
            sys.maxsize,
            -sys.maxsize - 1,
            10**100,  # Very large number
            -(10**100),  # Very small number
        ]

        for value in extreme_values:
            try:
                # Test numeric operations with extreme values
                if value == float("inf") or value == float("-inf"):
                    # Handle infinity
                    result = "infinity_handled"
                elif str(value) == "nan":
                    # Handle NaN
                    result = "nan_handled"
                else:
                    # Handle large numbers
                    result = f"extreme_value_{type(value).__name__}_handled"

                assert result is not None

            except (OverflowError, ValueError) as e:
                # Expected for extreme values
                assert "overflow" in str(e).lower() or "value" in str(e).lower()


@pytest.mark.integration
@pytest.mark.operational
class TestErrorHandlingIntegration:
    """Integration tests for error handling across components."""

    def test_cross_component_error_propagation(self):
        """Test error propagation across different components."""
        # Simulate error in one component affecting another
        component_a_error = None
        component_b_received_error = None

        def component_a():
            nonlocal component_a_error
            component_a_error = ValueError("Component A error")
            raise component_a_error

        def component_b():
            nonlocal component_b_received_error
            try:
                component_a()
            except Exception as e:
                component_b_received_error = e
                raise RuntimeError("Component B wrapping error") from e

        # Test error propagation
        with pytest.raises(RuntimeError) as exc_info:
            component_b()

        # Should preserve original error as cause
        assert exc_info.value.__cause__ is component_a_error
        assert component_b_received_error is component_a_error

    def test_error_recovery_integration(self):
        """Test integration of error recovery mechanisms."""
        recovery_attempts = []

        def failing_operation():
            recovery_attempts.append(len(recovery_attempts) + 1)
            if len(recovery_attempts) < 3:
                raise ConnectionError(f"Attempt {len(recovery_attempts)} failed")
            return "operation_successful"

        # Test retry logic
        max_retries = 3
        attempt = 0
        result = None

        while attempt < max_retries:
            attempt += 1
            try:
                result = failing_operation()
                break
            except ConnectionError:
                if attempt == max_retries:
                    raise
                continue

        # Should eventually succeed
        assert result == "operation_successful"
        assert len(recovery_attempts) == 3  # Should have failed twice, succeeded on third
