#!/usr/bin/env python3
"""
Advanced Error Handling Tests
=============================

This module contains advanced error handling tests for error recovery scenarios,
reporting/monitoring systems, boundary condition handling, and integration testing.

Author: Agent-2 (Architecture & Design Specialist)
Mission: Modularize test_error_handling.py for V2 compliance
License: MIT
"""

import sys
import time

import pytest

# Import error handling components
try:
    from src.core.unified_logging_system import UnifiedLoggingSystem

    from src.core.error_handling_unified import UnifiedErrorHandler

    ERROR_HANDLING_AVAILABLE = True
except ImportError:
    ERROR_HANDLING_AVAILABLE = False

    # Create mock classes
    class UnifiedErrorHandler:
        def handle_error(self, *args, **kwargs):
            return None

        def log_error(self, *args, **kwargs):
            return None

    class UnifiedLoggingSystem:
        def log_error(self, *args, **kwargs):
            pass


@pytest.mark.operational
class TestErrorRecoveryScenarios:
    """Test various error recovery scenarios."""

    def test_network_error_recovery(self):
        """Test recovery from network-related errors."""
        network_errors = [
            ConnectionError("Connection refused"),
            TimeoutError("Operation timed out"),
            OSError("Network unreachable"),
        ]

        for error in network_errors:
            with pytest.raises(type(error)):
                raise error

            # In real system, would test retry logic
            # For now, verify error types are correct

    def test_file_system_error_recovery(self):
        """Test recovery from file system errors."""
        file_errors = [
            FileNotFoundError("File not found"),
            PermissionError("Permission denied"),
            IsADirectoryError("Is a directory"),
            OSError("Disk full"),
        ]

        for error in file_errors:
            with pytest.raises(type(error)):
                raise error

    def test_resource_error_recovery(self):
        """Test recovery from resource exhaustion errors."""
        resource_errors = [
            MemoryError("Memory exhausted"),
            RecursionError("Maximum recursion depth exceeded"),
        ]

        for error in resource_errors:
            with pytest.raises(type(error)):
                raise error


@pytest.mark.operational
class TestErrorReportingAndMonitoring:
    """Test error reporting and monitoring systems."""

    def test_error_aggregation(self):
        """Test aggregation of multiple errors."""
        errors = []

        # Simulate multiple error scenarios
        error_scenarios = [
            (ValueError("Value error"), "input_validation"),
            (KeyError("Key error"), "data_processing"),
            (ConnectionError("Connection error"), "network_communication"),
            (TimeoutError("Timeout error"), "external_service"),
        ]

        for error, component in error_scenarios:
            error_info = {
                "error": str(error),
                "type": type(error).__name__,
                "component": component,
                "timestamp": time.time(),
            }
            errors.append(error_info)

        # Verify error aggregation
        assert len(errors) == len(error_scenarios)

        # Check error categorization
        error_types = [e["type"] for e in errors]
        assert "ValueError" in error_types
        assert "KeyError" in error_types
        assert "ConnectionError" in error_types
        assert "TimeoutError" in error_types

    def test_error_trending_analysis(self):
        """Test analysis of error trends over time."""
        # Simulate error patterns over time
        error_timeline = [
            {"timestamp": time.time(), "error_type": "ConnectionError", "component": "api"},
            {"timestamp": time.time() + 1, "error_type": "TimeoutError", "component": "api"},
            {"timestamp": time.time() + 2, "error_type": "ConnectionError", "component": "api"},
            {"timestamp": time.time() + 3, "error_type": "ValueError", "component": "processing"},
        ]

        # Analyze error patterns
        error_counts = {}
        component_errors = {}

        for error in error_timeline:
            error_type = error["error_type"]
            component = error["component"]

            error_counts[error_type] = error_counts.get(error_type, 0) + 1
            if component not in component_errors:
                component_errors[component] = {}
            component_errors[component][error_type] = (
                component_errors[component].get(error_type, 0) + 1
            )

        # Verify analysis
        assert error_counts["ConnectionError"] == 2
        assert error_counts["TimeoutError"] == 1
        assert error_counts["ValueError"] == 1

        assert "api" in component_errors
        assert "processing" in component_errors


@pytest.mark.operational
class TestBoundaryConditionHandling:
    """Test handling of boundary conditions and edge cases."""

    def test_null_and_empty_value_handling(self):
        """Test handling of null and empty values."""
        test_cases = [
            None,
            "",
            [],
            {},
            0,
            False,
        ]

        for test_value in test_cases:
            # Test that system can handle these values without crashing
            try:
                # Simulate processing of various input types
                if test_value is None:
                    result = "null_handled"
                elif test_value == "":
                    result = "empty_handled"
                elif isinstance(test_value, list) and len(test_value) == 0:
                    result = "empty_list_handled"
                elif isinstance(test_value, dict) and len(test_value) == 0:
                    result = "empty_dict_handled"
                else:
                    result = f"value_{test_value}_handled"

                assert result is not None
                assert "handled" in result

            except Exception as e:
                # Should handle edge cases gracefully
                assert "handled" in str(e).lower() or isinstance(e, (TypeError, ValueError))

    def test_extreme_value_handling(self):
        """Test handling of extreme values."""
        extreme_values = [
            float("inf"),
            float("-inf"),
            float("nan"),
            sys.maxsize,
            -sys.maxsize - 1,
            10**100,  # Very large number
            -(10**100),  # Very small number
        ]

        for value in extreme_values:
            try:
                # Test numeric operations with extreme values
                if value == float("inf") or value == float("-inf"):
                    # Handle infinity
                    result = "infinity_handled"
                elif str(value) == "nan":
                    # Handle NaN
                    result = "nan_handled"
                else:
                    # Handle large numbers
                    result = f"extreme_value_{type(value).__name__}_handled"

                assert result is not None

            except (OverflowError, ValueError) as e:
                # Expected for extreme values
                assert "handled" in str(e).lower() or isinstance(e, (OverflowError, ValueError))


@pytest.mark.operational
class TestErrorHandlingIntegration:
    """Integration tests for error handling system."""

    def test_cross_component_error_propagation(self):
        """Test error propagation across different components."""
        # Simulate error in one component affecting another
        component_a_error = None
        component_b_received_error = None

        def component_a():
            nonlocal component_a_error
            component_a_error = ValueError("Component A error")
            raise component_a_error

        def component_b():
            nonlocal component_b_received_error
            try:
                component_a()
            except Exception as e:
                component_b_received_error = e
                raise RuntimeError("Component B wrapping error") from e

        # Test error propagation
        with pytest.raises(RuntimeError) as exc_info:
            component_b()

        # Should preserve original error as cause
        assert exc_info.value.__cause__ is component_a_error
        assert component_b_received_error is component_a_error

    def test_error_recovery_integration(self):
        """Test integration of error recovery mechanisms."""
        recovery_attempts = []

        def failing_operation():
            recovery_attempts.append(len(recovery_attempts) + 1)
            if len(recovery_attempts) < 3:
                raise ConnectionError(f"Attempt {len(recovery_attempts)} failed")
            return "operation_successful"

        # Test retry logic
        max_retries = 3
        attempt = 0
        result = None

        while attempt < max_retries:
            attempt += 1
            try:
                result = failing_operation()
                break
            except ConnectionError:
                if attempt == max_retries:
                    raise
                continue

        # Should eventually succeed
        assert result == "operation_successful"
        assert len(recovery_attempts) == 3  # Should have failed twice, succeeded on third


if __name__ == "__main__":
    pytest.main([__file__, "-v", "--cov=src.core", "--cov-report=term-missing"])
