#!/usr/bin/env python3
"""
Core Error Handling Tests
=========================

This module contains core error handling tests for unified error handling,
exception management, and system resilience patterns.

Author: Agent-2 (Architecture & Design Specialist)
Mission: Modularize test_error_handling.py for V2 compliance
License: MIT
"""

import time
from unittest.mock import Mock, patch

import pytest

# Import error handling components
try:
    from src.core.unified_logging_system import UnifiedLoggingSystem

    from src.core.error_handling_unified import UnifiedErrorHandler

    ERROR_HANDLING_AVAILABLE = True
except ImportError:
    ERROR_HANDLING_AVAILABLE = False

    # Create mock classes
    class UnifiedErrorHandler:
        def handle_error(self, *args, **kwargs):
            return None

        def log_error(self, *args, **kwargs):
            return None

    class UnifiedLoggingSystem:
        def log_error(self, *args, **kwargs):
            pass


@pytest.mark.operational
class TestUnifiedErrorHandler:
    """Test unified error handling system."""

    def test_error_classification(self):
        """Test proper classification of different error types."""
        error_handler = UnifiedErrorHandler()

        test_errors = [
            (ValueError("Invalid value"), "ValueError"),
            (KeyError("Missing key"), "KeyError"),
            (FileNotFoundError("File not found"), "FileNotFoundError"),
            (ConnectionError("Connection failed"), "ConnectionError"),
            (TimeoutError("Operation timed out"), "TimeoutError"),
        ]

        for error, expected_type in test_errors:
            try:
                raise error
            except Exception as e:
                # Test error classification
                error_info = error_handler.handle_error(e)
                if error_info:
                    assert "error_type" in error_info
                    assert expected_type in error_info["error_type"]

    def test_error_logging(self):
        """Test error logging functionality."""
        error_handler = UnifiedErrorHandler()

        # Test logging various error types
        test_scenarios = [
            ValueError("Test value error"),
            RuntimeError("Test runtime error"),
            SystemError("Test system error"),
        ]

        for error in test_scenarios:
            # Should handle logging without raising exceptions
            try:
                error_handler.log_error(error, "test_component")
            except Exception as e:
                # Only acceptable if logging system itself has issues
                assert "log" in str(e).lower()

    def test_error_recovery_mechanisms(self):
        """Test error recovery and retry mechanisms."""
        error_handler = UnifiedErrorHandler()

        # Test retry logic
        retry_count = 0
        max_retries = 3

        def failing_operation():
            nonlocal retry_count
            retry_count += 1
            if retry_count < max_retries:
                raise ConnectionError("Temporary connection failure")
            return "success"

        # Test retry wrapper (if available)
        try:
            result = failing_operation()
            if retry_count >= max_retries:
                assert result == "success"
        except Exception:
            # If no retry mechanism, just ensure operation doesn't crash
            pass

    def test_graceful_degradation(self):
        """Test graceful degradation under error conditions."""
        error_handler = UnifiedErrorHandler()

        # Test system behavior when components fail
        with patch(
            "src.core.unified_logging_system.UnifiedLoggingSystem", create=True
        ) as mock_logging_class:
            mock_logger = Mock()
            mock_logger.log_error.side_effect = Exception("Logger failure")
            mock_logging_class.return_value = mock_logger

            # System should continue operating despite logger failure
            try:
                error_handler.log_error(ValueError("Test error"), "test_component")
                # Should not raise unhandled exceptions
            except Exception as e:
                # Only logger-related errors should propagate
                assert "log" in str(e).lower()


@pytest.mark.operational
class TestExceptionManagement:
    """Test comprehensive exception management."""

    def test_exception_chaining(self):
        """Test proper exception chaining and context preservation."""
        try:
            try:
                raise ValueError("Original error")
            except ValueError as original:
                raise RuntimeError("Wrapper error") from original
        except RuntimeError as wrapper:
            # Should preserve original exception
            assert wrapper.__cause__ is not None
            assert isinstance(wrapper.__cause__, ValueError)
            assert str(wrapper.__cause__) == "Original error"

    def test_custom_exception_hierarchy(self):
        """Test custom exception hierarchy for swarm system."""

        class SwarmException(Exception):
            """Base exception for swarm system."""

        class OperationalException(SwarmException):
            """Operational error."""

            pass

        class ConfigurationException(SwarmException):
            """Configuration error."""

            pass

        # Test exception hierarchy
        try:
            raise OperationalException("Test operational error")
        except SwarmException as e:
            assert isinstance(e, OperationalException)
            assert "operational" in str(e).lower()

        try:
            raise ConfigurationException("Test configuration error")
        except SwarmException as e:
            assert isinstance(e, ConfigurationException)
            assert "configuration" in str(e).lower()

    def test_error_context_preservation(self):
        """Test preservation of error context and debugging information."""

        def operation_with_context():
            """Simulate operation that provides context."""
            context = {
                "operation": "test_operation",
                "parameters": {"param1": "value1"},
                "timestamp": time.time(),
                "component": "test_component",
            }
            raise ValueError("Operation failed")

        try:
            operation_with_context()
        except ValueError as e:
            # Error should be catchable and context preservable
            assert "Operation failed" in str(e)

            # In a real system, context would be logged or attached
            # For testing, we verify the error is properly raised and catchable


@pytest.mark.operational
class TestSystemResilience:
    """Test system resilience and fault tolerance."""

    def test_service_degradation_handling(self):
        """Test handling of service degradation scenarios."""
        # Simulate service becoming unavailable
        service_available = True

        def unreliable_service():
            nonlocal service_available
            if not service_available:
                raise ConnectionError("Service temporarily unavailable")
            return "service_response"

        # Test with service available
        result = unreliable_service()
        assert result == "service_response"

        # Test with service unavailable
        service_available = False
        with pytest.raises(ConnectionError):
            unreliable_service()

    def test_circuit_breaker_pattern(self):
        """Test circuit breaker pattern for fault tolerance."""

        class CircuitBreaker:
            def __init__(self, failure_threshold=3):
                self.failure_count = 0
                self.failure_threshold = failure_threshold
                self.state = "closed"  # closed, open, half-open

            def call(self, operation):
                if self.state == "open":
                    raise Exception("Circuit breaker is open")

                try:
                    result = operation()
                    self._on_success()
                    return result
                except Exception as e:
                    self._on_failure()
                    raise e

            def _on_success(self):
                self.failure_count = 0
                self.state = "closed"

            def _on_failure(self):
                self.failure_count += 1
                if self.failure_count >= self.failure_threshold:
                    self.state = "open"

        breaker = CircuitBreaker()

        # Test successful operations
        result = breaker.call(lambda: "success")
        assert result == "success"
        assert breaker.state == "closed"

        # Test failure handling
        failure_count = 0

        def failing_operation():
            nonlocal failure_count
            failure_count += 1
            raise ValueError(f"Failure {failure_count}")

        # Should handle failures up to threshold
        for i in range(2):
            with pytest.raises(ValueError):
                breaker.call(failing_operation)

        # Should still be closed
        assert breaker.state == "closed"

        # Third failure should open circuit
        with pytest.raises(ValueError):
            breaker.call(failing_operation)
        assert breaker.state == "open"

        # Subsequent calls should fail fast
        with pytest.raises(Exception, match="Circuit breaker is open"):
            breaker.call(lambda: "should not execute")

    def test_fallback_mechanisms(self):
        """Test fallback mechanisms for service failures."""

        def primary_operation():
            raise ConnectionError("Primary service unavailable")

        def fallback_operation():
            return "fallback_response"

        # Test fallback execution
        result = None
        try:
            result = primary_operation()
        except ConnectionError:
            result = fallback_operation()

        assert result == "fallback_response"


if __name__ == "__main__":
    pytest.main([__file__, "-v", "--cov=src.core", "--cov-report=term-missing"])
