"""
Error Handling Integration Tests
=================================

Comprehensive integration tests for error handling modules and cross-service error scenarios.
Tests error propagation, recovery mechanisms, and resilience patterns across the V2_SWARM system.

Author: Agent-7 (Web Development Specialist)
Created: 2025-09-12
Coverage Target: 85%+ for all error handling modules
"""

import time
from unittest.mock import AsyncMock, Mock

import pytest

# Import error handling components
try:
    from src.core.error_handling.advanced_error_handler import AdvancedErrorHandler
    from src.core.error_handling.automated_recovery import AutomatedRecovery
    from src.core.error_handling.circuit_breaker import CircuitBreaker
    from src.core.error_handling.coordination_error_handler import CoordinationErrorHandler
    from src.core.error_handling.error_analysis_engine import ErrorAnalysisEngine
    from src.core.error_handling.error_recovery import ErrorRecovery
    from src.core.error_handling.retry_mechanisms import RetryMechanisms
    from src.core.error_handling.specialized_handlers import SpecializedHandlers

    ERROR_HANDLING_AVAILABLE = True
except ImportError as e:
    ERROR_HANDLING_AVAILABLE = False
    print(f"Warning: Error handling modules not fully available: {e}")

    # Create mock classes for testing
    class AdvancedErrorHandler:
        def __init__(self, *args, **kwargs):
            pass

        async def handle_error(self, *args, **kwargs):
            return None

    class AutomatedRecovery:
        def __init__(self, *args, **kwargs):
            pass

        def recover_from_error(self, *args, **kwargs):
            return True

    class CircuitBreaker:
        def __init__(self, *args, **kwargs):
            pass

        def call(self, *args, **kwargs):
            return None

    class CoordinationErrorHandler:
        def __init__(self, *args, **kwargs):
            pass

        async def handle_coordination_error(self, *args, **kwargs):
            return None

    class ErrorAnalysisEngine:
        def __init__(self, *args, **kwargs):
            pass

        def analyze_error(self, *args, **kwargs):
            return {"severity": "medium", "category": "test_error"}

    class ErrorRecovery:
        def __init__(self, *args, **kwargs):
            pass

        def recover(self, *args, **kwargs):
            return True

    class RetryMechanisms:
        def __init__(self, *args, **kwargs):
            pass

        async def execute_with_retry(self, *args, **kwargs):
            return None

    class SpecializedHandlers:
        def __init__(self, *args, **kwargs):
            pass

        def handle_specialized_error(self, *args, **kwargs):
            return None


@pytest.mark.integration
@pytest.mark.asyncio
class TestErrorHandlingIntegration:
    """Integration tests for error handling module interactions."""

    @pytest.fixture
    def error_components(self):
        """Fixture providing initialized error handling components."""
        return {
            "advanced_handler": AdvancedErrorHandler(),
            "automated_recovery": AutomatedRecovery(),
            "circuit_breaker": CircuitBreaker(failure_threshold=3, recovery_timeout=30),
            "coordination_handler": CoordinationErrorHandler(),
            "analysis_engine": ErrorAnalysisEngine(),
            "error_recovery": ErrorRecovery(),
            "retry_mechanisms": RetryMechanisms(),
            "specialized_handlers": SpecializedHandlers(),
        }

    @pytest.fixture
    def mock_messaging_service(self):
        """Mock messaging service for testing error scenarios."""
        mock_service = AsyncMock()
        mock_service.send_message = AsyncMock(return_value={"status": "success"})
        mock_service.receive_message = AsyncMock(return_value={"type": "test_message"})
        return mock_service

    @pytest.fixture
    def mock_vector_service(self):
        """Mock vector service for testing error scenarios."""
        mock_service = AsyncMock()
        mock_service.search_vectors = AsyncMock(return_value=[{"id": "test", "score": 0.95}])
        mock_service.add_vectors = AsyncMock(return_value={"status": "success"})
        return mock_service

    async def test_error_propagation_across_services(
        self, error_components, mock_messaging_service, mock_vector_service
    ):
        """Test error propagation and handling across multiple services."""
        # Setup error scenario
        mock_messaging_service.send_message.side_effect = Exception("Network timeout")
        mock_vector_service.search_vectors.side_effect = Exception("Vector search failed")

        # Test coordination error handler
        coordination_handler = error_components["coordination_handler"]
        analysis_engine = error_components["analysis_engine"]

        # Simulate cross-service error scenario
        error_context = {
            "service": "messaging",
            "operation": "send_message",
            "error": "Network timeout",
            "timestamp": time.time(),
            "correlation_id": "test-correlation-123",
        }

        # Test error analysis
        analysis_result = analysis_engine.analyze_error(error_context)
        assert analysis_result["severity"] in ["low", "medium", "high", "critical"]
        assert analysis_result["category"] != ""

        # Test coordination error handling
        result = await coordination_handler.handle_coordination_error(error_context)
        assert result is not None

        # Test automated recovery
        recovery = error_components["automated_recovery"]
        recovery_result = recovery.recover_from_error(error_context)
        assert isinstance(recovery_result, bool)

    async def test_circuit_breaker_integration(self, error_components):
        """Test circuit breaker integration with retry mechanisms."""
        circuit_breaker = error_components["circuit_breaker"]
        retry_mechanisms = error_components["retry_mechanisms"]

        # Mock failing function
        call_count = 0

        async def failing_function():
            nonlocal call_count
            call_count += 1
            if call_count < 4:  # Fail first 3 attempts
                raise Exception("Service unavailable")
            return "success"

        # Test circuit breaker with retry
        async def circuit_breaker_with_retry():
            return await retry_mechanisms.execute_with_retry(
                failing_function, max_attempts=5, backoff_factor=0.1
            )

        # Execute through circuit breaker
        result = await circuit_breaker.call(circuit_breaker_with_retry())

        # Verify behavior
        assert call_count >= 3  # Should have failed at least threshold times
        assert result == "success" or result is None

    def test_error_recovery_integration(self, error_components):
        """Test error recovery integration with specialized handlers."""
        error_recovery = error_components["error_recovery"]
        specialized_handlers = error_components["specialized_handlers"]

        # Test different error types
        error_scenarios = [
            {
                "type": "database_connection_error",
                "message": "Connection to database lost",
                "context": {"database": "main", "timeout": 30},
            },
            {
                "type": "api_rate_limit_error",
                "message": "API rate limit exceeded",
                "context": {"service": "external_api", "limit": 100, "reset_time": 60},
            },
            {
                "type": "file_system_error",
                "message": "Disk space exhausted",
                "context": {"filesystem": "/data", "available_space": 0},
            },
        ]

        for scenario in error_scenarios:
            # Test specialized handling
            specialized_result = specialized_handlers.handle_specialized_error(scenario)
            assert specialized_result is not None

            # Test recovery
            recovery_result = error_recovery.recover(scenario)
            assert isinstance(recovery_result, bool)

    async def test_cross_service_error_recovery(
        self, error_components, mock_messaging_service, mock_vector_service
    ):
        """Test error recovery across multiple services."""
        # Setup cascading failure scenario
        original_send = mock_messaging_service.send_message
        original_search = mock_vector_service.search_vectors

        call_sequence = []

        async def failing_send_message(*args, **kwargs):
            call_sequence.append("messaging_failed")
            raise Exception("Primary messaging service down")

        async def failing_search_vectors(*args, **kwargs):
            call_sequence.append("vector_failed")
            raise Exception("Vector service backup also down")

        mock_messaging_service.send_message = failing_send_message
        mock_vector_service.search_vectors = failing_search_vectors

        # Test comprehensive error handling
        advanced_handler = error_components["advanced_handler"]
        automated_recovery = error_components["automated_recovery"]

        error_context = {
            "operation": "cross_service_transaction",
            "services_involved": ["messaging", "vector"],
            "error_chain": ["messaging_failure", "vector_failure"],
            "business_impact": "high",
        }

        # Test advanced error handling
        try:
            await advanced_handler.handle_error(error_context)
        except Exception:
            pass  # Expected in failure scenario

        # Test automated recovery
        recovery_result = automated_recovery.recover_from_error(error_context)
        assert isinstance(recovery_result, bool)

        # Verify call sequence
        assert "messaging_failed" in call_sequence

    def test_error_analysis_engine_integration(self, error_components):
        """Test error analysis engine with various error patterns."""
        analysis_engine = error_components["analysis_engine"]

        # Test different error patterns
        test_errors = [
            {
                "error": Exception("Connection timeout"),
                "context": {"service": "database", "operation": "connect"},
                "expected_category": "connection_error",
            },
            {
                "error": ValueError("Invalid input parameter"),
                "context": {"service": "validation", "operation": "validate"},
                "expected_category": "validation_error",
            },
            {
                "error": PermissionError("Access denied"),
                "context": {"service": "filesystem", "operation": "write"},
                "expected_category": "permission_error",
            },
            {
                "error": RuntimeError("Unexpected system state"),
                "context": {"service": "state_machine", "operation": "transition"},
                "expected_category": "runtime_error",
            },
        ]

        for test_case in test_errors:
            analysis_result = analysis_engine.analyze_error(
                {"error": test_case["error"], "context": test_case["context"]}
            )

            assert "severity" in analysis_result
            assert "category" in analysis_result
            assert analysis_result["severity"] in ["low", "medium", "high", "critical"]
            assert analysis_result["category"] != ""

    async def test_retry_mechanisms_with_circuit_breaker(self, error_components):
        """Test retry mechanisms working with circuit breaker patterns."""
        retry_mechanisms = error_components["retry_mechanisms"]
        circuit_breaker = error_components["circuit_breaker"]

        # Track execution attempts
        attempt_log = []

        async def unreliable_operation(attempt_number):
            attempt_log.append(f"attempt_{attempt_number}")
            if attempt_number < 3:
                raise Exception(f"Attempt {attempt_number} failed")
            return f"success_on_attempt_{attempt_number}"

        # Test retry with circuit breaker
        async def operation_with_retry():
            return await retry_mechanisms.execute_with_retry(
                lambda: unreliable_operation(len(attempt_log) + 1),
                max_attempts=5,
                backoff_factor=0.01,  # Fast for testing
            )

        # Execute through circuit breaker
        result = await circuit_breaker.call(operation_with_retry())

        # Verify behavior
        assert len(attempt_log) >= 3  # Should have failed initial attempts
        assert result is not None or len(attempt_log) >= 5  # Either succeeded or exhausted retries

    def test_error_handling_performance_under_load(self, error_components):
        """Test error handling performance under simulated load."""
        import concurrent.futures

        advanced_handler = error_components["advanced_handler"]
        analysis_engine = error_components["analysis_engine"]

        # Generate concurrent error scenarios
        def worker_thread(thread_id):
            results = []
            for i in range(10):  # 10 errors per thread
                error_context = {
                    "thread_id": thread_id,
                    "error_id": i,
                    "error": Exception(f"Thread {thread_id} error {i}"),
                    "timestamp": time.time(),
                }

                # Test analysis engine performance
                start_time = time.time()
                analysis_result = analysis_engine.analyze_error(error_context)
                end_time = time.time()

                results.append(
                    {
                        "thread_id": thread_id,
                        "error_id": i,
                        "analysis_time": end_time - start_time,
                        "result": analysis_result,
                    }
                )

            return results

        # Run concurrent error handling
        with concurrent.futures.ThreadPoolExecutor(max_workers=5) as executor:
            futures = [executor.submit(worker_thread, i) for i in range(5)]
            all_results = []

            for future in concurrent.futures.as_completed(futures):
                all_results.extend(future.result())

        # Verify performance
        assert len(all_results) == 50  # 5 threads * 10 errors each

        # Check performance metrics
        analysis_times = [r["analysis_time"] for r in all_results]
        avg_analysis_time = sum(analysis_times) / len(analysis_times)
        max_analysis_time = max(analysis_times)

        # Performance should be reasonable (< 0.1s per analysis on average)
        assert avg_analysis_time < 0.1, f"Average analysis time too slow: {avg_analysis_time:.3f}s"
        assert max_analysis_time < 1.0, f"Max analysis time too slow: {max_analysis_time:.3f}s"

    async def test_chaos_engineering_error_scenarios(self, error_components):
        """Test chaos engineering error scenarios for resilience validation."""
        circuit_breaker = error_components["circuit_breaker"]
        automated_recovery = error_components["automated_recovery"]

        # Define chaos scenarios
        chaos_scenarios = [
            {
                "name": "rapid_failures",
                "description": "Simulate rapid consecutive failures",
                "failure_pattern": [True] * 10,  # 10 consecutive failures
                "expected_behavior": "circuit_breaker_open",
            },
            {
                "name": "intermittent_failures",
                "description": "Simulate intermittent failure pattern",
                "failure_pattern": [True, False, True, False, True, False],
                "expected_behavior": "recovery_attempted",
            },
            {
                "name": "gradual_recovery",
                "description": "Simulate gradual service recovery",
                "failure_pattern": [True, True, True, False, False, False],
                "expected_behavior": "circuit_breaker_closed",
            },
        ]

        for scenario in chaos_scenarios:
            failure_index = 0

            async def chaos_operation():
                nonlocal failure_index
                should_fail = (
                    failure_index < len(scenario["failure_pattern"])
                    and scenario["failure_pattern"][failure_index]
                )
                failure_index += 1

                if should_fail:
                    raise Exception(f"Chaos scenario: {scenario['name']}")
                return "operation_successful"

            # Reset circuit breaker state
            circuit_breaker._failure_count = 0
            circuit_breaker._state = "closed"

            # Execute chaos scenario
            results = []
            for _ in range(len(scenario["failure_pattern"])):
                try:
                    result = await circuit_breaker.call(chaos_operation())
                    results.append("success" if result else "failure")
                except Exception:
                    results.append("failure")

            # Test automated recovery
            recovery_context = {
                "scenario": scenario["name"],
                "failure_pattern": scenario["failure_pattern"],
                "results": results,
            }

            recovery_result = automated_recovery.recover_from_error(recovery_context)
            assert isinstance(recovery_result, bool)

    def test_error_metrics_and_reporting_integration(self, error_components):
        """Test error metrics collection and reporting integration."""
        analysis_engine = error_components["analysis_engine"]

        # Generate various errors for metrics testing
        error_types = ["connection_error", "timeout_error", "validation_error", "permission_error"]
        severities = ["low", "medium", "high", "critical"]

        test_errors = []
        for i in range(20):  # Generate 20 test errors
            error_context = {
                "error_type": error_types[i % len(error_types)],
                "severity": severities[i % len(severities)],
                "timestamp": time.time() + i,
                "service": f"service_{i % 3}",
                "operation": f"operation_{i % 5}",
            }
            test_errors.append(error_context)

        # Process errors and collect metrics
        processed_errors = []
        for error in test_errors:
            result = analysis_engine.analyze_error(error)
            processed_errors.append(result)

        # Verify metrics collection
        assert len(processed_errors) == len(test_errors)

        # Check error distribution
        severity_counts = {}
        category_counts = {}

        for result in processed_errors:
            severity = result.get("severity", "unknown")
            category = result.get("category", "unknown")

            severity_counts[severity] = severity_counts.get(severity, 0) + 1
            category_counts[category] = category_counts.get(category, 0) + 1

        # Verify we have reasonable distribution
        assert len(severity_counts) > 0
        assert len(category_counts) > 0
        assert sum(severity_counts.values()) == len(test_errors)


@pytest.mark.integration
@pytest.mark.parametrize(
    "error_type",
    [
        "network_timeout",
        "database_connection_lost",
        "api_rate_limit_exceeded",
        "file_system_full",
        "memory_exhaustion",
        "service_unavailable",
    ],
)
async def test_error_type_specific_handling(error_type, error_components):
    """Test error type specific handling strategies."""
    specialized_handlers = error_components["specialized_handlers"]
    error_recovery = error_components["error_recovery"]

    # Define error scenarios by type
    error_scenarios = {
        "network_timeout": {
            "error": TimeoutError("Connection timed out"),
            "context": {"timeout": 30, "retries": 3},
            "expected_recovery_strategy": "retry_with_backoff",
        },
        "database_connection_lost": {
            "error": ConnectionError("Database connection lost"),
            "context": {"database": "main", "pool_size": 10},
            "expected_recovery_strategy": "connection_pool_refresh",
        },
        "api_rate_limit_exceeded": {
            "error": Exception("Rate limit exceeded"),
            "context": {"limit": 100, "reset_time": 60},
            "expected_recovery_strategy": "exponential_backoff",
        },
        "file_system_full": {
            "error": OSError("No space left on device"),
            "context": {"filesystem": "/data", "cleanup_required": True},
            "expected_recovery_strategy": "disk_cleanup",
        },
        "memory_exhaustion": {
            "error": MemoryError("Memory exhausted"),
            "context": {"process": "worker", "memory_limit": "1GB"},
            "expected_recovery_strategy": "memory_cleanup",
        },
        "service_unavailable": {
            "error": Exception("Service temporarily unavailable"),
            "context": {"service": "external_api", "retry_after": 30},
            "expected_recovery_strategy": "circuit_breaker",
        },
    }

    scenario = error_scenarios[error_type]

    # Test specialized handling
    handling_result = specialized_handlers.handle_specialized_error(scenario)
    assert handling_result is not None

    # Test recovery strategy
    recovery_result = error_recovery.recover(scenario)
    assert isinstance(recovery_result, bool)

    # Verify error context is preserved
    assert "error" in scenario
    assert "context" in scenario


@pytest.mark.integration
class TestErrorHandlingBoundaries:
    """Test error handling at system boundaries."""

    async def test_error_boundary_isolation(self):
        """Test that errors in one component don't affect others."""
        # This would test actual component isolation in a real system
        # For now, we'll mock the behavior

        # Mock components that should be isolated
        component_a = AsyncMock()
        component_b = AsyncMock()

        component_a.process = AsyncMock(side_effect=Exception("Component A failed"))
        component_b.process = AsyncMock(return_value="Component B success")

        # Simulate boundary isolation
        try:
            await component_a.process()
        except Exception:
            pass  # Error should be contained

        # Component B should still work
        result_b = await component_b.process()
        assert result_b == "Component B success"

    def test_error_boundary_logging(self):
        """Test that errors are properly logged at boundaries."""
        # Mock logging system
        mock_logger = Mock()

        # Simulate error boundary with logging
        try:
            raise ValueError("Test boundary error")
        except Exception as e:
            mock_logger.error(f"Boundary error caught: {e}")

        # Verify logging occurred
        mock_logger.error.assert_called_once()
        call_args = mock_logger.error.call_args[0][0]
        assert "Boundary error caught" in call_args
        assert "Test boundary error" in call_args

    async def test_error_boundary_recovery(self):
        """Test recovery mechanisms at system boundaries."""
        recovery_attempts = []

        async def failing_operation():
            recovery_attempts.append("attempt")
            if len(recovery_attempts) < 3:
                raise Exception("Boundary operation failed")
            return "boundary_operation_success"

        # Test boundary recovery
        max_attempts = 5
        attempt = 0
        result = None

        while attempt < max_attempts:
            attempt += 1
            try:
                result = await failing_operation()
                break
            except Exception:
                if attempt == max_attempts:
                    raise

        assert result == "boundary_operation_success"
        assert len(recovery_attempts) == 3  # Should succeed on 3rd attempt


if __name__ == "__main__":
    pytest.main([__file__, "-v", "--cov=src.core.error_handling", "--cov-report=term-missing"])
